import XCTest
import Combine

@testable import Sync


class RetriableOperationTests: XCTestCase {
    var retrySignal: PassthroughSubject<Void, Never>!
    var backgroundTaskManager: MockBackgroundTaskManager!

    override func setUp() {
        retrySignal = .init()
        backgroundTaskManager = MockBackgroundTaskManager()

        backgroundTaskManager.stubBeginTask { _, _ in return 0 }
        backgroundTaskManager.stubEndTask { _ in }
    }

    func subject(
        retrySignal: AnyPublisher<Void, Never>? = nil,
        backgroundTaskManager: BackgroundTaskManager? = nil,
        operation: SyncOperation
    ) -> RetriableOperation {
        RetriableOperation(
            retrySignal: retrySignal ?? self.retrySignal.eraseToAnyPublisher(),
            backgroundTaskManager: backgroundTaskManager ?? self.backgroundTaskManager,
            operation: operation
        )
    }

    func test_retry_retriesOnSignal() {
        var calls = 0
        let firstAttempt = expectation(description: "first attempt")
        let secondAttempt = expectation(description: "second attempt")

        let operation = TestSyncOperation { () -> SyncOperationResult in
            defer { calls += 1 }

            switch calls {
            case 0:
                firstAttempt.fulfill()
                return .retry(TestError.anError)
            case 1:
                secondAttempt.fulfill()
                return .success
            default:
                XCTFail("Received unexpected number of calls: \(calls)")
                return .failure(TestError.anError)
            }
        }

        let executor = subject(operation: operation)

        let completed = expectation(description: "it completed")
        let queue = OperationQueue()
        queue.addOperation(executor)
        queue.addBarrierBlock {
            completed.fulfill()
        }

        wait(for: [firstAttempt], timeout: 1)
        retrySignal.send()
        wait(for: [secondAttempt, completed], timeout: 1, enforceOrder: true)
    }

    func test_retry_whenMaxRetriesAreExceeded_doesNotRetry() {
        var calls = 0

        let expectations = [
            expectation(description: "first attempt"),
            expectation(description: "second attempt"),
            expectation(description: "third attempt"),
        ]

        let operation = TestSyncOperation { () -> SyncOperationResult in
            guard calls <= 3 else {
                XCTFail("Max retries exceeded")
                return .failure(TestError.anError)
            }

            expectations[calls].fulfill()
            calls += 1
            return .retry(TestError.anError)
        }

        let executor = subject(operation: operation)
        let completed = expectation(description: "it completed")
        let queue = OperationQueue()
        queue.addOperation(executor)
        queue.addBarrierBlock {
            completed.fulfill()
        }

        expectations.forEach {
            wait(for: [$0], timeout: 1)
            retrySignal.send()
        }

        wait(for: [completed], timeout: 1, enforceOrder: true)
    }

    func test_main_protectsOperationWithBackgroundTask() {
        let beganOperation = expectation(description: "began operation")
        let operation = TestSyncOperation {
            beganOperation.fulfill()
        }

        let executor = subject(operation: operation)

        let queue = OperationQueue()
        queue.addOperation(executor)

        wait(for: [beganOperation], timeout: 1)
        XCTAssertNotNil(backgroundTaskManager.beginTaskCall(at: 0))

        queue.waitUntilAllOperationsAreFinished()
        XCTAssertEqual(backgroundTaskManager.endTaskCall(at: 0)?.identifier, 0)
    }
}
